<?xml version="1.0"?>
<robot xmlns:xacro="http://ros.org/wiki/xacro">

  <xacro:macro name="wheel" params="name parent *origin">

    <!-- link: wheel -->
    <link name="${name}_wheel">
      <origin xyz="0 0 0" rpy="${PI/2} 0 0"/>
      <xacro:create_sphere m="1" r="${body_scale/20}">
        <origin xyz="0 0 0" rpy="0 0 0"/>
      </xacro:create_sphere>
    </link>

    <!-- joint: parent_base -> wheel -->
    <joint name="${parent}_to_${name}_wheel" type="continuous">
      <xacro:insert_block name="origin" />
      <parent link="${parent}"/>
      <child link="${name}_wheel"/>
      <axis xyz="0 1 0"/>
    </joint>

  </xacro:macro>

</robot>
